I'm sorry, but an uncaught exception occurred.

While running game code:
  File "game/script.rpy", line 598, in script
    leo "Grazie per aver visitato il Setificio!"
Exception: Sayer 'leo' is not defined.

-- Full Traceback ------------------------------------------------------------

Full traceback:
  File "game/script.rpy", line 598, in script
    leo "Grazie per aver visitato il Setificio!"
  File "C:\Users\Gabriele2.T.EGINA\Documents\renpy-8.2.3-sdk\renpy\ast.py", line 2560, in execute
    Say.execute(self)
  File "C:\Users\Gabriele2.T.EGINA\Documents\renpy-8.2.3-sdk\renpy\ast.py", line 575, in execute
    who = eval_who(self.who, self.who_fast)
  File "C:\Users\Gabriele2.T.EGINA\Documents\renpy-8.2.3-sdk\renpy\ast.py", line 464, in eval_who
    raise Exception("Sayer '%s' is not defined." % who)
Exception: Sayer 'leo' is not defined.

Windows-10-10.0.22631 AMD64
Ren'Py 8.2.3.24061702
Setificio dev 1.0
Mon Aug  5 11:28:11 2024
